2024-04-21 20:29:55,514 FILE: creds.py IN: create_new_token MESSAGE: Ошибка получения iam_token.txt: HTTPConnectionPool(host='169.254.169.254', port=80): Max retries exceeded with url: /computeMetadata/v1/instance/service-accounts/default/token (Caused by ConnectTimeoutError(<urllib3.connection.HTTPConnection object at 0x000001A4FC987BD0>, 'Connection to 169.254.169.254 timed out. (connect timeout=None)'))
